<robot name="robo_2d">

<link name="base">
    
    <visual name="">
        <origin xyz="0.0 0.0 0.0" rpy="0.0 0.0 0.0"/>
        <geometry>
<<<<<<< HEAD
<<<<<<< HEAD
            <box size="0.2 0.15 0.025"/>
=======
            <box size="0.2 0.025 0.15"/>
>>>>>>> 5a3f4bc... Uploading the created package with URDf
=======
            <box size="0.2 0.15 0.025"/>
>>>>>>> 38e6f06... updated .gitignore
        </geometry>
        <material name="">
            <color rgba="1.0 0.0 0.0 1.0"/>
            <texture filename=""/>
        </material>
    </visual>

</link>

<link name="link1">

    <visual name="">
<<<<<<< HEAD
<<<<<<< HEAD
        <origin xyz="-0.025 0.0 0.15" rpy="0.0 0.0 0.0"/>
        <geometry>
            <box size="0.25 0.15 0.5"/>
=======
        <origin xyz="-0.025 0.15 0.0" rpy="0.0 0.0 0.0"/>
        <geometry>
            <box size="0.25 0.5 0.15"/>
>>>>>>> 5a3f4bc... Uploading the created package with URDf
=======
        <origin xyz="-0.025 0.0 0.15" rpy="0.0 0.0 0.0"/>
        <geometry>
            <box size="0.25 0.15 0.5"/>
>>>>>>> 38e6f06... updated .gitignore
        </geometry>
        <material name="">
            <color rgba="1 1 1 1"/>
            <texture filename=""/>
        </material>
    </visual>

</link>

<link name="link2">

    <visual name="">
<<<<<<< HEAD
<<<<<<< HEAD
        <origin xyz="0.0 0.0 0.25" rpy="0.0 0.0 0.0"/>
        <geometry>
            <box size="0.25 0.15 0.5"/>
=======
        <origin xyz="0.0 0.25 0.0" rpy="0.0 0.0 0.0"/>
        <geometry>
            <box size="0.25 0.5 0.15"/>
>>>>>>> 5a3f4bc... Uploading the created package with URDf
=======
        <origin xyz="0.0 0.0 0.25" rpy="0.0 0.0 0.0"/>
        <geometry>
            <box size="0.25 0.15 0.5"/>
>>>>>>> 38e6f06... updated .gitignore
        </geometry>
        <material name="">
            <color rgba="1 1 0.5 1"/>
            <texture filename=""/>
        </material>
    </visual>

</link>

<link name="endlink">
 
    <visual name="">
        <origin xyz="0.0 0.0 0.0" rpy="0.0 0.0 0.0"/>
        <geometry>
            <box size="0.0 0.0 0.0"/>
        </geometry>
        <material name="">
            <color rgba="1.0 0.0 0.0 1.0"/>
            <texture filename=""/>
        </material>
    </visual>

</link>


<joint name="joint1" type="continuous">
<<<<<<< HEAD
<<<<<<< HEAD
    <origin xyz="0.025 0.0 0.1" rpy="0.0 0.0 0.0"/>
=======
    <origin xyz="0.025 0.1 0.0" rpy="0.0 0.0 0.0"/>
>>>>>>> 5a3f4bc... Uploading the created package with URDf
=======
    <origin xyz="0.025 0.0 0.1" rpy="0.0 0.0 0.0"/>
>>>>>>> 38e6f06... updated .gitignore
    <parent link="base"/>
    <child link="link1"/>
    <axis xyz="0.0 1 0.0"/>
 
</joint>

<joint name="joint2" type="continuous">
<<<<<<< HEAD
<<<<<<< HEAD
    <origin xyz="-0.025 0.0 0.4" rpy="0.0 0.0 0.0"/>
=======
    <origin xyz="-0.025 0.4 0.0" rpy="0.0 0.0 0.0"/>
>>>>>>> 5a3f4bc... Uploading the created package with URDf
=======
    <origin xyz="-0.025 0.0 0.4" rpy="0.0 0.0 0.0"/>
>>>>>>> 38e6f06... updated .gitignore
    <parent link="link1"/>
    <child link="link2"/>
    <axis xyz="0.0 1 0.0"/>

</joint>

<joint name="end_effector" type="fixed">
    <origin xyz="0.0 0.0 0.0" rpy="0.0 0.0 0.0"/>
    <parent link="link2"/>
    <child link="endlink"/>
</joint>
<<<<<<< HEAD

</robot>

=======
    
<<<<<<< HEAD
<<<<<<< HEAD
</robot>
>>>>>>> 5a3f4bc... Uploading the created package with URDf
=======


</robot>
>>>>>>> a55f8e7... changed axis of rotation
=======
    
    
</robot>
>>>>>>> 38e6f06... updated .gitignore
