<robot name="robo_2d">

    <link name="base">
        
        <visual name="">
            <origin xyz="0.0 0.0 0.0" rpy="0.0 0.0 0.0"/>
            <geometry>
                <box size="0.0 0.0 0.0"/>
            </geometry>
            <material name="">
                <color rgba="1.0 0.0 0.0 1.0"/>
            </material>
        </visual>

    </link>

    <link name="link1">

        <visual name="">
            <origin xyz="2.5 0.0 0.0" rpy="0.0 0.0 0.0"/>
            <geometry>
                <box size="5 0.25 1"/>
            </geometry>
            <material name="white">
                <color rgba="1 1 1 1"/>
            </material>
        </visual>

    </link>

    <link name="link2">

        <visual name="">
            <origin xyz="2.5 0.0 0.0" rpy="0.0 0.0 0.0"/>
            <geometry>
                <box size="5 0.25 1"/>
            </geometry>
            <material name="purple">
                <color rgba="0.7 0.3 0.5 1"/>
            </material>
        </visual>

    </link>

    <link name="endlink">
    
        <visual name="">
            <origin xyz="2.5 0.0 0.0" rpy="0.0 0.0 0.0"/>
            <geometry>
                <box size="0.0 0.0 0.0"/>
            </geometry>
            <material name="">
                <color rgba="1.0 0.0 0.0 1.0"/>
            </material>
        </visual>

    </link>


    <joint name="joint1" type="continuous">
        <origin xyz="0.0 0.0 0.0" rpy="0.0 0.0 0.0"/>
        <parent link="base"/>
        <child link="link1"/>
        <axis xyz="0.0 -1 0.0"/>
    
    </joint>

    <joint name="joint2" type="continuous">
        <origin xyz="5 0.0 0.0" rpy="0.0 0.0 0.0"/>
        <parent link="link1"/>
        <child link="link2"/>
        <axis xyz="0.0 -1 0.0"/>

    </joint>

    <joint name="end_effector" type="fixed">
        <origin xyz="2.5 0.0 0.0"/>
        <parent link="link2"/>
        <child link="endlink"/>
    </joint>

</robot>
